Workbook

Sheet Xulosa
A1: 📊 SerMebel — Xulosa
A2: 📅 Davr: | B2: 46296 | C2: gacha: | D2: 46326 | E2: ← ikkala sanani ikki marta bosing — kalendar ochiladi
A4: 🔴 Xarajatlar | C4: 🟢 Daromadlar | E4: 💠 Balans | G4: 💸 Xodimlarga berildi | I4: 👔 Rahbarga (shaxsiy) | K4: 🏠 Uy uchun (shaxsiy)
A5: =-SUMIFS(Amallar!G:G,Amallar!F:F,"Chiqim",Amallar!K:K,"<>otkazma",Amallar!K:K,"<>rahbarga",Amallar!K:K,"<>uy",Amallar!Q:Q,"<>Ha",Amallar!B:B,">="&INT($B$2),Amallar!B:B,"<="&$D$2) -> -401667092 | C5: =SUMIFS(Amallar!G:G,Amallar!F:F,"Kirim",Amallar!K:K,"<>rahbar",Amallar!K:K,"<>otkazma",Amallar!Q:Q,"<>Ha",Amallar!B:B,">="&INT($B$2),Amallar!B:B,"<="&$D$2) -> 504450732 | E5: =A5+C5 -> 102783640 | G5: =SUMIFS(Amallar!G:G,Amallar!F:F,"Kirim",Amallar!K:K,"rahbar",Amallar!Q:Q,"<>Ha",Amallar!B:B,">="&INT($B$2),Amallar!B:B,"<="&$D$2) -> 115784414 | I5: =SUMIFS(Amallar!G:G,Amallar!F:F,"Chiqim",Amallar!K:K,"rahbarga",Amallar!Q:Q,"<>Ha",Amallar!B:B,">="&INT($B$2),Amallar!B:B,"<="&$D$2) -> 21893470 | K5: =SUMIFS(Amallar!G:G,Amallar!F:F,"Chiqim",Amallar!K:K,"uy",Amallar!Q:Q,"<>Ha",Amallar!B:B,">="&INT($B$2),Amallar!B:B,"<="&$D$2) -> 18866170
A7: Xarajatlar turlari bo'yicha
A8: Kategoriya | B8: Summa | C8: Operatsiya | D8: Ulushi
A9: 👷 Ойлик (ish haqi) | B9: =SUMIFS(Amallar!G:G,Amallar!F:F,"Chiqim",Amallar!K:K,"oylik",Amallar!Q:Q,"<>Ha",Amallar!B:B,">="&INT($B$2),Amallar!B:B,"<="&$D$2) -> 139981627 | C9: =COUNTIFS(Amallar!F:F,"Chiqim",Amallar!K:K,"oylik",Amallar!Q:Q,"<>Ha",Amallar!B:B,">="&INT($B$2),Amallar!B:B,"<="&$D$2) -> 73 | D9: =IFERROR(B9/-$A$5,0) -> 0.34850161
A10: 🪵 Заказ материал | B10: =SUMIFS(Amallar!G:G,Amallar!F:F,"Chiqim",Amallar!K:K,"material",Amallar!Q:Q,"<>Ha",Amallar!B:B,">="&INT($B$2),Amallar!B:B,"<="&$D$2) -> 131612440 | C10: =COUNTIFS(Amallar!F:F,"Chiqim",Amallar!K:K,"material",Amallar!Q:Q,"<>Ha",Amallar!B:B,">="&INT($B$2),Amallar!B:B,"<="&$D$2) -> 15 | D10: =IFERROR(B10/-$A$5,0) -> 0.32766548
A11: 🏭 Завод продукта | B11: =SUMIFS(Amallar!G:G,Amallar!F:F,"Chiqim",Amallar!K:K,"zavod",Amallar!Q:Q,"<>Ha",Amallar!B:B,">="&INT($B$2),Amallar!B:B,"<="&$D$2) -> 3600270 | C11: =COUNTIFS(Amallar!F:F,"Chiqim",Amallar!K:K,"zavod",Amallar!Q:Q,"<>Ha",Amallar!B:B,">="&INT($B$2),Amallar!B:B,"<="&$D$2) -> 4 | D11: =IFERROR(B11/-$A$5,0) -> 0.0089633183
A12: 🔩 Furnitura | B12: =SUMIFS(Amallar!G:G,Amallar!F:F,"Chiqim",Amallar!K:K,"furnitura",Amallar!Q:Q,"<>Ha",Amallar!B:B,">="&INT($B$2),Amallar!B:B,"<="&$D$2) -> 27707896 | C12: =COUNTIFS(Amallar!F:F,"Chiqim",Amallar!K:K,"furnitura",Amallar!Q:Q,"<>Ha",Amallar!B:B,">="&INT($B$2),Amallar!B:B,"<="&$D$2) -> 25 | D12: =IFERROR(B12/-$A$5,0) -> 0.068982241
A13: 🚚 Mashina / dostavka | B13: =SUMIFS(Amallar!G:G,Amallar!F:F,"Chiqim",Amallar!K:K,"mashina",Amallar!Q:Q,"<>Ha",Amallar!B:B,">="&INT($B$2),Amallar!B:B,"<="&$D$2) -> 2676000 | C13: =COUNTIFS(Amallar!F:F,"Chiqim",Amallar!K:K,"mashina",Amallar!Q:Q,"<>Ha",Amallar!B:B,">="&INT($B$2),Amallar!B:B,"<="&$D$2) -> 13 | D13: =IFERROR(B13/-$A$5,0) -> 0.0066622336
A14: ⛽ Zapravka | B14: =SUMIFS(Amallar!G:G,Amallar!F:F,"Chiqim",Amallar!K:K,"zapravka",Amallar!Q:Q,"<>Ha",Amallar!B:B,">="&INT($B$2),Amallar!B:B,"<="&$D$2) -> 6645000 | C14: =COUNTIFS(Amallar!F:F,"Chiqim",Amallar!K:K,"zapravka",Amallar!Q:Q,"<>Ha",Amallar!B:B,">="&INT($B$2),Amallar!B:B,"<="&$D$2) -> 24 | D14: =IFERROR(B14/-$A$5,0) -> 0.016543551
A15: 🔧 Remont avto | B15: =SUMIFS(Amallar!G:G,Amallar!F:F,"Chiqim",Amallar!K:K,"remont",Amallar!Q:Q,"<>Ha",Amallar!B:B,">="&INT($B$2),Amallar!B:B,"<="&$D$2) -> 550000 | C15: =COUNTIFS(Amallar!F:F,"Chiqim",Amallar!K:K,"remont",Amallar!Q:Q,"<>Ha",Amallar!B:B,">="&INT($B$2),Amallar!B:B,"<="&$D$2) -> 4 | D15: =IFERROR(B15/-$A$5,0) -> 0.0013692932
A16: 💡 Kommunal xizmatlar | B16: =SUMIFS(Amallar!G:G,Amallar!F:F,"Chiqim",Amallar!K:K,"kommunal",Amallar!Q:Q,"<>Ha",Amallar!B:B,">="&INT($B$2),Amallar!B:B,"<="&$D$2) -> 673921 | C16: =COUNTIFS(Amallar!F:F,"Chiqim",Amallar!K:K,"kommunal",Amallar!Q:Q,"<>Ha",Amallar!B:B,">="&INT($B$2),Amallar!B:B,"<="&$D$2) -> 12 | D16: =IFERROR(B16/-$A$5,0) -> 0.0016778098
A17: 🛎 Usluga (xizmatlar) | B17: =SUMIFS(Amallar!G:G,Amallar!F:F,"Chiqim",Amallar!K:K,"usluga",Amallar!Q:Q,"<>Ha",Amallar!B:B,">="&INT($B$2),Amallar!B:B,"<="&$D$2) -> 30830486 | C17: =COUNTIFS(Amallar!F:F,"Chiqim",Amallar!K:K,"usluga",Amallar!Q:Q,"<>Ha",Amallar!B:B,">="&INT($B$2),Amallar!B:B,"<="&$D$2) -> 17 | D17: =IFERROR(B17/-$A$5,0) -> 0.076756315
A18: 📣 СММ / reklama | B18: =SUMIFS(Amallar!G:G,Amallar!F:F,"Chiqim",Amallar!K:K,"smm",Amallar!Q:Q,"<>Ha",Amallar!B:B,">="&INT($B$2),Amallar!B:B,"<="&$D$2) -> 9994057 | C18: =COUNTIFS(Amallar!F:F,"Chiqim",Amallar!K:K,"smm",Amallar!Q:Q,"<>Ha",Amallar!B:B,">="&INT($B$2),Amallar!B:B,"<="&$D$2) -> 12 | D18: =IFERROR(B18/-$A$5,0) -> 0.024881443
A19: 🗂 Ofis uchun | B19: =SUMIFS(Amallar!G:G,Amallar!F:F,"Chiqim",Amallar!K:K,"ofis",Amallar!Q:Q,"<>Ha",Amallar!B:B,">="&INT($B$2),Amallar!B:B,"<="&$D$2) -> 33499395 | C19: =COUNTIFS(Amallar!F:F,"Chiqim",Amallar!K:K,"ofis",Amallar!Q:Q,"<>Ha",Amallar!B:B,">="&INT($B$2),Amallar!B:B,"<="&$D$2) -> 26 | D19: =IFERROR(B19/-$A$5,0) -> 0.083400895
A20: 🛠 Asbob-uskuna | B20: =SUMIFS(Amallar!G:G,Amallar!F:F,"Chiqim",Amallar!K:K,"asbob",Amallar!Q:Q,"<>Ha",Amallar!B:B,">="&INT($B$2),Amallar!B:B,"<="&$D$2) -> 2450000 | C20: =COUNTIFS(Amallar!F:F,"Chiqim",Amallar!K:K,"asbob",Amallar!Q:Q,"<>Ha",Amallar!B:B,">="&INT($B$2),Amallar!B:B,"<="&$D$2) -> 4 | D20: =IFERROR(B20/-$A$5,0) -> 0.0060995786
A21: 🍽 Ovqat | B21: =SUMIFS(Amallar!G:G,Amallar!F:F,"Chiqim",Amallar!K:K,"ovqat",Amallar!Q:Q,"<>Ha",Amallar!B:B,">="&INT($B$2),Amallar!B:B,"<="&$D$2) -> 11056000 | C21: =COUNTIFS(Amallar!F:F,"Chiqim",Amallar!K:K,"ovqat",Amallar!Q:Q,"<>Ha",Amallar!B:B,">="&INT($B$2),Amallar!B:B,"<="&$D$2) -> 115 | D21: =IFERROR(B21/-$A$5,0) -> 0.027525282
A22: 🔁 Peredelka (qayta ishlash) | B22: =SUMIFS(Amallar!G:G,Amallar!F:F,"Chiqim",Amallar!K:K,"peredelka",Amallar!Q:Q,"<>Ha",Amallar!B:B,">="&INT($B$2),Amallar!B:B,"<="&$D$2) -> 0 | C22: =COUNTIFS(Amallar!F:F,"Chiqim",Amallar!K:K,"peredelka",Amallar!Q:Q,"<>Ha",Amallar!B:B,">="&INT($B$2),Amallar!B:B,"<="&$D$2) -> 0 | D22: =IFERROR(B22/-$A$5,0) -> 0
A23: 📦 Boshqa | B23: =SUMIFS(Amallar!G:G,Amallar!F:F,"Chiqim",Amallar!K:K,"boshqa",Amallar!Q:Q,"<>Ha",Amallar!B:B,">="&INT($B$2),Amallar!B:B,"<="&$D$2) -> 390000 | C23: =COUNTIFS(Amallar!F:F,"Chiqim",Amallar!K:K,"boshqa",Amallar!Q:Q,"<>Ha",Amallar!B:B,">="&INT($B$2),Amallar!B:B,"<="&$D$2) -> 4 | D23: =IFERROR(B23/-$A$5,0) -> 0.00097095333
A24: JAMI | B24: =SUM(B9:B23) -> 401667092 | C24: =SUM(C9:C23) -> 348 | D24: =IF(B24>0,1,0) -> 1
A26: Daromadlar turlari bo'yicha
A27: Turi | B27: Summa | C27: Operatsiya | D27: Izoh
A28: 💰 Avans (yangi zakaz) | B28: =SUMIFS(Amallar!G:G,Amallar!F:F,"Kirim",Amallar!K:K,"avans",Amallar!Q:Q,"<>Ha",Amallar!B:B,">="&INT($B$2),Amallar!B:B,"<="&$D$2) -> 258528980 | C28: =COUNTIFS(Amallar!F:F,"Kirim",Amallar!K:K,"avans",Amallar!Q:Q,"<>Ha",Amallar!B:B,">="&INT($B$2),Amallar!B:B,"<="&$D$2) -> 8
A29: ✅ Qoldiq to'lov (bitgan zakaz) | B29: =SUMIFS(Amallar!G:G,Amallar!F:F,"Kirim",Amallar!K:K,"qoldiq",Amallar!Q:Q,"<>Ha",Amallar!B:B,">="&INT($B$2),Amallar!B:B,"<="&$D$2) -> 237189282 | C29: =COUNTIFS(Amallar!F:F,"Kirim",Amallar!K:K,"qoldiq",Amallar!Q:Q,"<>Ha",Amallar!B:B,">="&INT($B$2),Amallar!B:B,"<="&$D$2) -> 9
A30: 👔 Rahbardan | B30: =SUMIFS(Amallar!G:G,Amallar!F:F,"Kirim",Amallar!K:K,"rahbar",Amallar!Q:Q,"<>Ha",Amallar!B:B,">="&INT($B$2),Amallar!B:B,"<="&$D$2) -> 115784414 | C30: =COUNTIFS(Amallar!F:F,"Kirim",Amallar!K:K,"rahbar",Amallar!Q:Q,"<>Ha",Amallar!B:B,">="&INT($B$2),Amallar!B:B,"<="&$D$2) -> 23 | D30: ichki o'tkazma — daromadga kirmaydi
A31: ↩️ Qaytim / vozvrat | B31: =SUMIFS(Amallar!G:G,Amallar!F:F,"Kirim",Amallar!K:K,"qaytim",Amallar!Q:Q,"<>Ha",Amallar!B:B,">="&INT($B$2),Amallar!B:B,"<="&$D$2) -> 0 | C31: =COUNTIFS(Amallar!F:F,"Kirim",Amallar!K:K,"qaytim",Amallar!Q:Q,"<>Ha",Amallar!B:B,">="&INT($B$2),Amallar!B:B,"<="&$D$2) -> 0
A32: 📥 Boshqa kirim | B32: =SUMIFS(Amallar!G:G,Amallar!F:F,"Kirim",Amallar!K:K,"boshqa_kirim",Amallar!Q:Q,"<>Ha",Amallar!B:B,">="&INT($B$2),Amallar!B:B,"<="&$D$2) -> 8732470 | C32: =COUNTIFS(Amallar!F:F,"Kirim",Amallar!K:K,"boshqa_kirim",Amallar!Q:Q,"<>Ha",Amallar!B:B,">="&INT($B$2),Amallar!B:B,"<="&$D$2) -> 1
A34: Hamyonlar (xodimlar)
A35: Xodim | B35: Oyda berildi | C35: Oyda sarfladi | D35: Hamyonda (jami) | E35: Oylik hisob
A36: 💼 МирМуxаммад Файзуллаев (rahbar) | B36: =SUMIFS(Amallar!G:G,Amallar!D:D,443142649,Amallar!F:F,"Kirim",Amallar!Q:Q,"<>Ha",Amallar!B:B,">="&INT($B$2),Amallar!B:B,"<="&$D$2) -> 504450732 | C36: =SUMIFS(Amallar!G:G,Amallar!D:D,443142649,Amallar!F:F,"Chiqim",Amallar!K:K,"<>otkazma",Amallar!Q:Q,"<>Ha",Amallar!B:B,">="&INT($B$2),Amallar!B:B,"<="&$D$2) -> 327869325 | D36: — kassa | E36: ="—" -> —
A37: 👤 °°•• Gafurov Islom ••°° | B37: =SUMIFS(Amallar!G:G,Amallar!D:D,254366051,Amallar!F:F,"Kirim",Amallar!Q:Q,"<>Ha",Amallar!B:B,">="&INT($B$2),Amallar!B:B,"<="&$D$2) -> 100257414 | C37: =SUMIFS(Amallar!G:G,Amallar!D:D,254366051,Amallar!F:F,"Chiqim",Amallar!K:K,"<>otkazma",Amallar!Q:Q,"<>Ha",Amallar!B:B,">="&INT($B$2),Amallar!B:B,"<="&$D$2) -> 99656407 | D37: =SUMIFS(Amallar!G:G,Amallar!D:D,254366051,Amallar!F:F,"Kirim",Amallar!Q:Q,"<>Ha")-SUMIFS(Amallar!G:G,Amallar!D:D,254366051,Amallar!F:F,"Chiqim",Amallar!Q:Q,"<>Ha") -> 601007 | E37: =IF(COUNTIFS('Oylik hisob'!A:A,254366051,'Oylik hisob'!C:C,TEXT($B$2,"yyyy-mm"))>0,"✅ topshirdi","⏳ yo'q") -> ⏳ yo'q
A38: 👤 Umid Yusupov | B38: =SUMIFS(Amallar!G:G,Amallar!D:D,6156487883,Amallar!F:F,"Kirim",Amallar!Q:Q,"<>Ha",Amallar!B:B,">="&INT($B$2),Amallar!B:B,"<="&$D$2) -> 91508500 | C38: =SUMIFS(Amallar!G:G,Amallar!D:D,6156487883,Amallar!F:F,"Chiqim",Amallar!K:K,"<>otkazma",Amallar!Q:Q,"<>Ha",Amallar!B:B,">="&INT($B$2),Amallar!B:B,"<="&$D$2) -> 14901000 | D38: =SUMIFS(Amallar!G:G,Amallar!D:D,6156487883,Amallar!F:F,"Kirim",Amallar!Q:Q,"<>Ha")-SUMIFS(Amallar!G:G,Amallar!D:D,6156487883,Amallar!F:F,"Chiqim",Amallar!Q:Q,"<>Ha") -> 626000 | E38: =IF(COUNTIFS('Oylik hisob'!A:A,6156487883,'Oylik hisob'!C:C,TEXT($B$2,"yyyy-mm"))>0,"✅ topshirdi","⏳ yo'q") -> ⏳ yo'q
A39: JAMI | B39: =SUM(B36:B38) -> 696216646 | C39: =SUM(C36:C38) -> 442426732 | D39: =SUM(D36:D38) -> 1227007 | E39: =IF(C39=-$A$5+$I$5+$K$5,"✅ xarajatlar bilan teng","⚠️ farq: "&TEXT(-$A$5+$I$5+$K$5-C39,"#,##0")) -> ✅ xarajatlar bilan teng
A40: 👷 Oylik — kimga
A41: Ism | B41: Oyda berildi | C41: Bo'lim | D41: Lavozim
A42: Dilmurod | B42: =SUMIFS(Amallar!G:G,Amallar!F:F,"Chiqim",Amallar!K:K,"oylik",Amallar!R:R,"Dilmurod",Amallar!Q:Q,"<>Ha",Amallar!B:B,">="&INT($B$2),Amallar!B:B,"<="&$D$2) -> 20991106 | C42: 1-komanda (sborka-ustanovka) | D42: bosh usta
A43: Jamshid | B43: =SUMIFS(Amallar!G:G,Amallar!F:F,"Chiqim",Amallar!K:K,"oylik",Amallar!R:R,"Jamshid",Amallar!Q:Q,"<>Ha",Amallar!B:B,">="&INT($B$2),Amallar!B:B,"<="&$D$2) -> 20000 | C43: 1-komanda (sborka-ustanovka) | D43: sherik
A44: Jalol | B44: =SUMIFS(Amallar!G:G,Amallar!F:F,"Chiqim",Amallar!K:K,"oylik",Amallar!R:R,"Jalol",Amallar!Q:Q,"<>Ha",Amallar!B:B,">="&INT($B$2),Amallar!B:B,"<="&$D$2) -> 820000 | C44: 1-komanda (sborka-ustanovka) | D44: sherik
...

Sheet Xarajat puli
A1: 💸 Xarajat puli — ish uchun bergan pullaringiz (oylikka qo'shilmaydi) | P1: =IFERROR(__xludf.DUMMYFUNCTION("IFERROR(FILTER(Xodimlar!B2:B500,Xodimlar!D2:D500=""xodim""),"""")"),"°°•• Gafurov Islom ••°°") -> °°•• Gafurov Islom ••°°
A2: Oyliklari alohida: «👷 Ishchi kartasi» (Islom, Umid). Bu yerda faqat siz ish xarajati uchun bergan pul va u nimaga sarflangani. | P2: =IFERROR(__xludf.DUMMYFUNCTION("""COMPUTED_VALUE"""),"Umid Yusupov") -> Umid Yusupov
A3: 👤 Xodimni tanlang: | B3: °°•• Gafurov Islom ••°° | E3: ← katakni bosing: Umid Yusupov yoki Gafurov Islom | P3: =IFERROR(__xludf.DUMMYFUNCTION("""COMPUTED_VALUE"""),"Maftuna Turgʻunboyeva") -> Maftuna Turgʻunboyeva
A4: 📅 Davr: | B4: 46023 | C4: gacha: | D4: 46387 | E4: ← ikkala sanani ham ikki marta bosing — kalendar ochiladi | P4: =IFERROR(__xludf.DUMMYFUNCTION("""COMPUTED_VALUE"""),"NAFISA") -> NAFISA
A6: 💸 Sizdan olgan | B6: 🔴 Ish uchun sarflagan | C6: 👛 Qo'lida qolgan | D6: 📝 Necha marta olgan
A7: =SUMIFS(Amallar!G:G,Amallar!E:E,$B$3,Amallar!F:F,"Kirim",Amallar!K:K,"rahbar",Amallar!Q:Q,"<>Ha",Amallar!B:B,">="&$B$4,Amallar!B:B,"<"&($D$4+1)) -> 100257414 | B7: =SUMIFS(Amallar!G:G,Amallar!E:E,$B$3,Amallar!F:F,"Chiqim",Amallar!Q:Q,"<>Ha",Amallar!B:B,">="&$B$4,Amallar!B:B,"<"&($D$4+1)) -> 99656407 | C7: =SUMIFS(Amallar!G:G,Amallar!E:E,$B$3,Amallar!F:F,"Kirim",Amallar!Q:Q,"<>Ha")-SUMIFS(Amallar!G:G,Amallar!E:E,$B$3,Amallar!F:F,"Chiqim",Amallar!Q:Q,"<>Ha") -> 601007 | D7: =COUNTIFS(Amallar!E:E,$B$3,Amallar!F:F,"Kirim",Amallar!K:K,"rahbar",Amallar!Q:Q,"<>Ha",Amallar!B:B,">="&$B$4,Amallar!B:B,"<"&($D$4+1)) -> 13
A9: 📥 Sizdan olgan pullari | F9: 🔴 Nimaga sarflagan (har biri) | M9: 📊 Turlari bo'yicha
A10: Sana | B10: Summa (so'm) | C10: Dollarda | D10: Sabab / izoh | F10: Sana | G10: Vaqt | H10: Turi | I10: Summa (so'm) | J10: Buyurtma ID | K10: Izoh
A11: =IFERROR(__xludf.DUMMYFUNCTION("IFERROR(ARRAYFORMULA(SORT(FILTER({Amallar!B2:B500,Amallar!G2:G500,IF(Amallar!H2:H500=""USD"",Amallar!I2:I500&"" $"",""""),Amallar!N2:N500},Amallar!E2:E500=$B$3,Amallar!F2:F500=""Kirim"",Amallar!K2:K500=""rahbar"",Amallar!Q2:Q500<>""Ha"",Amallar!B2:B500>=$"&"B$4,Amallar!B2:B500<$D$4+1),1,FALSE)),""— yozuv yo'q"")"),46321.0) -> 46321 | B11: =IFERROR(__xludf.DUMMYFUNCTION("""COMPUTED_VALUE"""),1200000.0) -> 1200000 | C11: =IFERROR(__xludf.DUMMYFUNCTION("""COMPUTED_VALUE"""),"") | D11: =IFERROR(__xludf.DUMMYFUNCTION("""COMPUTED_VALUE"""),"So'rov #12: Харажатга") -> So'rov #12: Харажатга | F11: =IFERROR(__xludf.DUMMYFUNCTION("IFERROR(SORT(FILTER({Amallar!B2:B500,Amallar!C2:C500,Amallar!L2:L500,Amallar!G2:G500,Amallar!M2:M500,Amallar!N2:N500},Amallar!E2:E500=$B$3,Amallar!F2:F500=""Chiqim"",Amallar!Q2:Q500<>""Ha"",Amallar!B2:B500>=$B$4,Amallar!B2:B500<$D$4+1),1,FALSE,2,FALSE),"""&"— sarf yo'q"")"),46322.0) -> 46322 | G11: =IFERROR(__xludf.DUMMYFUNCTION("""COMPUTED_VALUE"""),0.6493055555555556) -> 0.64930556 | H11: =IFERROR(__xludf.DUMMYFUNCTION("""COMPUTED_VALUE"""),"Заказ материал") -> Заказ материал | I11: =IFERROR(__xludf.DUMMYFUNCTION("""COMPUTED_VALUE"""),516000.0) -> 516000 | J11: =IFERROR(__xludf.DUMMYFUNCTION("""COMPUTED_VALUE"""),389.0) -> 389 | K11: =IFERROR(__xludf.DUMMYFUNCTION("""COMPUTED_VALUE"""),"Мдф декор овал") -> Мдф декор овал | M11: =IFERROR(__xludf.DUMMYFUNCTION("IFERROR(QUERY(FILTER({Amallar!L2:L500,Amallar!G2:G500},Amallar!E2:E500=$B$3,Amallar!F2:F500=""Chiqim"",Amallar!Q2:Q500<>""Ha"",Amallar!B2:B500>=$B$4,Amallar!B2:B500<$D$4+1),""select Col1, sum(Col2), count(Col2) group by Col1 order by sum(Col2) desc label "&"Col1 'Turi', sum(Col2) 'Summa', count(Col2) 'Soni'"",0),""—"")"),"Turi") -> Turi | N11: =IFERROR(__xludf.DUMMYFUNCTION("""COMPUTED_VALUE"""),"Summa") -> Summa | O11: =IFERROR(__xludf.DUMMYFUNCTION("""COMPUTED_VALUE"""),"Soni") -> Soni
A12: =IFERROR(__xludf.DUMMYFUNCTION("""COMPUTED_VALUE"""),46319.0) -> 46319 | B12: =IFERROR(__xludf.DUMMYFUNCTION("""COMPUTED_VALUE"""),3570000.0) -> 3570000 | C12: =IFERROR(__xludf.DUMMYFUNCTION("""COMPUTED_VALUE"""),"300 $") -> 300 $ | D12: =IFERROR(__xludf.DUMMYFUNCTION("""COMPUTED_VALUE"""),"So'rov #11: Харажатга") -> So'rov #11: Харажатга | F12: =IFERROR(__xludf.DUMMYFUNCTION("""COMPUTED_VALUE"""),46322.0) -> 46322 | G12: =IFERROR(__xludf.DUMMYFUNCTION("""COMPUTED_VALUE"""),0.6145833333333334) -> 0.61458333 | H12: =IFERROR(__xludf.DUMMYFUNCTION("""COMPUTED_VALUE"""),"Ovqat") -> Ovqat | I12: =IFERROR(__xludf.DUMMYFUNCTION("""COMPUTED_VALUE"""),35000.0) -> 35000 | K12: =IFERROR(__xludf.DUMMYFUNCTION("""COMPUTED_VALUE"""),"Обед озим") -> Обед озим | M12: =IFERROR(__xludf.DUMMYFUNCTION("""COMPUTED_VALUE"""),"Заказ материал") -> Заказ материал | N12: =IFERROR(__xludf.DUMMYFUNCTION("""COMPUTED_VALUE"""),4.0786E7) -> 40786000 | O12: =IFERROR(__xludf.DUMMYFUNCTION("""COMPUTED_VALUE"""),4.0) -> 4
A13: =IFERROR(__xludf.DUMMYFUNCTION("""COMPUTED_VALUE"""),46318.0) -> 46318 | B13: =IFERROR(__xludf.DUMMYFUNCTION("""COMPUTED_VALUE"""),1200000.0) -> 1200000 | C13: =IFERROR(__xludf.DUMMYFUNCTION("""COMPUTED_VALUE"""),"") | D13: =IFERROR(__xludf.DUMMYFUNCTION("""COMPUTED_VALUE"""),"So'rov #10: Харажатга") -> So'rov #10: Харажатга | F13: =IFERROR(__xludf.DUMMYFUNCTION("""COMPUTED_VALUE"""),46321.0) -> 46321 | G13: =IFERROR(__xludf.DUMMYFUNCTION("""COMPUTED_VALUE"""),0.8965277777777778) -> 0.89652778 | H13: =IFERROR(__xludf.DUMMYFUNCTION("""COMPUTED_VALUE"""),"Ойлик (ish haqi)") -> Ойлик (ish haqi) | I13: =IFERROR(__xludf.DUMMYFUNCTION("""COMPUTED_VALUE"""),200000.0) -> 200000 | K13: =IFERROR(__xludf.DUMMYFUNCTION("""COMPUTED_VALUE"""),"Ойлик") -> Ойлик | M13: =IFERROR(__xludf.DUMMYFUNCTION("""COMPUTED_VALUE"""),"Usluga (xizmatlar)") -> Usluga (xizmatlar) | N13: =IFERROR(__xludf.DUMMYFUNCTION("""COMPUTED_VALUE"""),3.0612486E7) -> 30612486 | O13: =IFERROR(__xludf.DUMMYFUNCTION("""COMPUTED_VALUE"""),14.0) -> 14
A14: =IFERROR(__xludf.DUMMYFUNCTION("""COMPUTED_VALUE"""),46314.0) -> 46314 | B14: =IFERROR(__xludf.DUMMYFUNCTION("""COMPUTED_VALUE"""),1205590.0) -> 1205590 | C14: =IFERROR(__xludf.DUMMYFUNCTION("""COMPUTED_VALUE"""),"100 $") -> 100 $ | D14: =IFERROR(__xludf.DUMMYFUNCTION("""COMPUTED_VALUE"""),"So'rov #9: харажатга") -> So'rov #9: харажатга | F14: =IFERROR(__xludf.DUMMYFUNCTION("""COMPUTED_VALUE"""),46321.0) -> 46321 | G14: =IFERROR(__xludf.DUMMYFUNCTION("""COMPUTED_VALUE"""),0.7263888888888889) -> 0.72638889 | H14: =IFERROR(__xludf.DUMMYFUNCTION("""COMPUTED_VALUE"""),"Zapravka") -> Zapravka | I14: =IFERROR(__xludf.DUMMYFUNCTION("""COMPUTED_VALUE"""),252000.0) -> 252000 | K14: =IFERROR(__xludf.DUMMYFUNCTION("""COMPUTED_VALUE"""),"Газ") -> Газ | M14: =IFERROR(__xludf.DUMMYFUNCTION("""COMPUTED_VALUE"""),"Furnitura") -> Furnitura | N14: =IFERROR(__xludf.DUMMYFUNCTION("""COMPUTED_VALUE"""),1.8926E7) -> 18926000 | O14: =IFERROR(__xludf.DUMMYFUNCTION("""COMPUTED_VALUE"""),20.0) -> 20
A15: =IFERROR(__xludf.DUMMYFUNCTION("""COMPUTED_VALUE"""),46314.0) -> 46314 | B15: =IFERROR(__xludf.DUMMYFUNCTION("""COMPUTED_VALUE"""),6.75E7) -> 67500000 | C15: =IFERROR(__xludf.DUMMYFUNCTION("""COMPUTED_VALUE"""),"5625 $") -> 5625 $ | D15: =IFERROR(__xludf.DUMMYFUNCTION("""COMPUTED_VALUE"""),"Qarzlaga") -> Qarzlaga | F15: =IFERROR(__xludf.DUMMYFUNCTION("""COMPUTED_VALUE"""),46321.0) -> 46321 | G15: =IFERROR(__xludf.DUMMYFUNCTION("""COMPUTED_VALUE"""),0.7256944444444444) -> 0.72569444 | H15: =IFERROR(__xludf.DUMMYFUNCTION("""COMPUTED_VALUE"""),"Zapravka") -> Zapravka | I15: =IFERROR(__xludf.DUMMYFUNCTION("""COMPUTED_VALUE"""),402000.0) -> 402000 | K15: =IFERROR(__xludf.DUMMYFUNCTION("""COMPUTED_VALUE"""),"Газ") -> Газ | M15: =IFERROR(__xludf.DUMMYFUNCTION("""COMPUTED_VALUE"""),"Zapravka") -> Zapravka | N15: =IFERROR(__xludf.DUMMYFUNCTION("""COMPUTED_VALUE"""),4635000.0) -> 4635000 | O15: =IFERROR(__xludf.DUMMYFUNCTION("""COMPUTED_VALUE"""),17.0) -> 17
A16: =IFERROR(__xludf.DUMMYFUNCTION("""COMPUTED_VALUE"""),46313.0) -> 46313 | B16: =IFERROR(__xludf.DUMMYFUNCTION("""COMPUTED_VALUE"""),1196000.0) -> 1196000 | C16: =IFERROR(__xludf.DUMMYFUNCTION("""COMPUTED_VALUE"""),"100 $") -> 100 $ | D16: =IFERROR(__xludf.DUMMYFUNCTION("""COMPUTED_VALUE"""),"Расход") -> Расход | F16: =IFERROR(__xludf.DUMMYFUNCTION("""COMPUTED_VALUE"""),46321.0) -> 46321 | G16: =IFERROR(__xludf.DUMMYFUNCTION("""COMPUTED_VALUE"""),0.4583333333333333) -> 0.45833333 | H16: =IFERROR(__xludf.DUMMYFUNCTION("""COMPUTED_VALUE"""),"Kommunal xizmatlar") -> Kommunal xizmatlar | I16: =IFERROR(__xludf.DUMMYFUNCTION("""COMPUTED_VALUE"""),50000.0) -> 50000 | K16: =IFERROR(__xludf.DUMMYFUNCTION("""COMPUTED_VALUE"""),"Газ ишхона") -> Газ ишхона | M16: =IFERROR(__xludf.DUMMYFUNCTION("""COMPUTED_VALUE"""),"Ойлик (ish haqi)") -> Ойлик (ish haqi) | N16: =IFERROR(__xludf.DUMMYFUNCTION("""COMPUTED_VALUE"""),2452000.0) -> 2452000 | O16: =IFERROR(__xludf.DUMMYFUNCTION("""COMPUTED_VALUE"""),26.0) -> 26
A17: =IFERROR(__xludf.DUMMYFUNCTION("""COMPUTED_VALUE"""),46310.0) -> 46310 | B17: =IFERROR(__xludf.DUMMYFUNCTION("""COMPUTED_VALUE"""),1790000.0) -> 1790000 | C17: =IFERROR(__xludf.DUMMYFUNCTION("""COMPUTED_VALUE"""),"") | D17: =IFERROR(__xludf.DUMMYFUNCTION("""COMPUTED_VALUE"""),"So'rov #7: Расходга") -> So'rov #7: Расходга | F17: =IFERROR(__xludf.DUMMYFUNCTION("""COMPUTED_VALUE"""),46321.0) -> 46321 | G17: =IFERROR(__xludf.DUMMYFUNCTION("""COMPUTED_VALUE"""),0.4576388888888889) -> 0.45763889 | H17: =IFERROR(__xludf.DUMMYFUNCTION("""COMPUTED_VALUE"""),"Zapravka") -> Zapravka | I17: =IFERROR(__xludf.DUMMYFUNCTION("""COMPUTED_VALUE"""),100000.0) -> 100000 | K17: =IFERROR(__xludf.DUMMYFUNCTION("""COMPUTED_VALUE"""),"Райхоникига бензин") -> Райхоникига бензин | M17: =IFERROR(__xludf.DUMMYFUNCTION("""COMPUTED_VALUE"""),"Ovqat") -> Ovqat | N17: =IFERROR(__xludf.DUMMYFUNCTION("""COMPUTED_VALUE"""),1251000.0) -> 1251000 | O17: =IFERROR(__xludf.DUMMYFUNCTION("""COMPUTED_VALUE"""),24.0) -> 24
A18: =IFERROR(__xludf.DUMMYFUNCTION("""COMPUTED_VALUE"""),46309.0) -> 46309 | B18: =IFERROR(__xludf.DUMMYFUNCTION("""COMPUTED_VALUE"""),1200000.0) -> 1200000 | C18: =IFERROR(__xludf.DUMMYFUNCTION("""COMPUTED_VALUE"""),"") | D18: =IFERROR(__xludf.DUMMYFUNCTION("""COMPUTED_VALUE"""),"So'rov #5: Расходша") -> So'rov #5: Расходша | F18: =IFERROR(__xludf.DUMMYFUNCTION("""COMPUTED_VALUE"""),46321.0) -> 46321 | G18: =IFERROR(__xludf.DUMMYFUNCTION("""COMPUTED_VALUE"""),0.4576388888888889) -> 0.45763889 | H18: =IFERROR(__xludf.DUMMYFUNCTION("""COMPUTED_VALUE"""),"Kommunal xizmatlar") -> Kommunal xizmatlar | I18: =IFERROR(__xludf.DUMMYFUNCTION("""COMPUTED_VALUE"""),50000.0) -> 50000 | K18: =IFERROR(__xludf.DUMMYFUNCTION("""COMPUTED_VALUE"""),"Свет ишхона") -> Свет ишхона | M18: =IFERROR(__xludf.DUMMYFUNCTION("""COMPUTED_VALUE"""),"Kommunal xizmatlar") -> Kommunal xizmatlar | N18: =IFERROR(__xludf.DUMMYFUNCTION("""COMPUTED_VALUE"""),553921.0) -> 553921 | O18: =IFERROR(__xludf.DUMMYFUNCTION("""COMPUTED_VALUE"""),10.0) -> 10
A19: =IFERROR(__xludf.DUMMYFUNCTION("""COMPUTED_VALUE"""),46305.0) -> 46305 | B19: =IFERROR(__xludf.DUMMYFUNCTION("""COMPUTED_VALUE"""),1180000.0) -> 1180000 | C19: =IFERROR(__xludf.DUMMYFUNCTION("""COMPUTED_VALUE"""),"100 $") -> 100 $ | D19: =IFERROR(__xludf.DUMMYFUNCTION("""COMPUTED_VALUE"""),"Расход") -> Расход | F19: =IFERROR(__xludf.DUMMYFUNCTION("""COMPUTED_VALUE"""),46320.0) -> 46320 | G19: =IFERROR(__xludf.DUMMYFUNCTION("""COMPUTED_VALUE"""),0.46875) -> 0.46875 | H19: =IFERROR(__xludf.DUMMYFUNCTION("""COMPUTED_VALUE"""),"Boshqa") -> Boshqa | I19: =IFERROR(__xludf.DUMMYFUNCTION("""COMPUTED_VALUE"""),110000.0) -> 110000 | K19: =IFERROR(__xludf.DUMMYFUNCTION("""COMPUTED_VALUE"""),"Штраф чанган Жумака") -> Штраф чанган Жумака | M19: =IFERROR(__xludf.DUMMYFUNCTION("""COMPUTED_VALUE"""),"Boshqa") -> Boshqa | N19: =IFERROR(__xludf.DUMMYFUNCTION("""COMPUTED_VALUE"""),240000.0) -> 240000 | O19: =IFERROR(__xludf.DUMMYFUNCTION("""COMPUTED_VALUE"""),3.0) -> 3
A20: =IFERROR(__xludf.DUMMYFUNCTION("""COMPUTED_VALUE"""),46305.0) -> 46305 | B20: =IFERROR(__xludf.DUMMYFUNCTION("""COMPUTED_VALUE"""),1.665706E7) -> 16657060 | C20: =IFERROR(__xludf.DUMMYFUNCTION("""COMPUTED_VALUE"""),"1400 $") -> 1400 $ | D20: =IFERROR(__xludf.DUMMYFUNCTION("""COMPUTED_VALUE"""),"Азимга") -> Азимга | F20: =IFERROR(__xludf.DUMMYFUNCTION("""COMPUTED_VALUE"""),46320.0) -> 46320 | G20: =IFERROR(__xludf.DUMMYFUNCTION("""COMPUTED_VALUE"""),0.41875) -> 0.41875 | H20: =IFERROR(__xludf.DUMMYFUNCTION("""COMPUTED_VALUE"""),"Furnitura") -> Furnitura | I20: =IFERROR(__xludf.DUMMYFUNCTION("""COMPUTED_VALUE"""),809200.0) -> 809200 | J20: =IFERROR(__xludf.DUMMYFUNCTION("""COMPUTED_VALUE"""),402.0) -> 402 | K20: =IFERROR(__xludf.DUMMYFUNCTION("""COMPUTED_VALUE"""),"Краска") -> Краска | M20: =IFERROR(__xludf.DUMMYFUNCTION("""COMPUTED_VALUE"""),"Rahbarga (shaxsiy)") -> Rahbarga (shaxsiy) | N20: =IFERROR(__xludf.DUMMYFUNCTION("""COMPUTED_VALUE"""),100000.0) -> 100000 | O20: =IFERROR(__xludf.DUMMYFUNCTION("""COMPUTED_VALUE"""),3.0) -> 3
A21: =IFERROR(__xludf.DUMMYFUNCTION("""COMPUTED_VALUE"""),46304.0) -> 46304 | B21: =IFERROR(__xludf.DUMMYFUNCTION("""COMPUTED_VALUE"""),1200000.0) -> 1200000 | C21: =IFERROR(__xludf.DUMMYFUNCTION("""COMPUTED_VALUE"""),"") | D21: =IFERROR(__xludf.DUMMYFUNCTION("""COMPUTED_VALUE"""),"So'rov #2: Харажатга") -> So'rov #2: Харажатга | F21: =IFERROR(__xludf.DUMMYFUNCTION("""COMPUTED_VALUE"""),46320.0) -> 46320 | G21: =IFERROR(__xludf.DUMMYFUNCTION("""COMPUTED_VALUE"""),0.41805555555555557) -> 0.41805556 | H21: =IFERROR(__xludf.DUMMYFUNCTION("""COMPUTED_VALUE"""),"Furnitura") -> Furnitura | I21: =IFERROR(__xludf.DUMMYFUNCTION("""COMPUTED_VALUE"""),1689800.0) -> 1689800 | J21: =IFERROR(__xludf.DUMMYFUNCTION("""COMPUTED_VALUE"""),392.0) -> 392 | K21: =IFERROR(__xludf.DUMMYFUNCTION("""COMPUTED_VALUE"""),"Астар раствор") -> Астар раствор | M21: =IFERROR(__xludf.DUMMYFUNCTION("""COMPUTED_VALUE"""),"Mashina / dostavka") -> Mashina / dostavka | N21: =IFERROR(__xludf.DUMMYFUNCTION("""COMPUTED_VALUE"""),50000.0) -> 50000 | O21: =IFERROR(__xludf.DUMMYFUNCTION("""COMPUTED_VALUE"""),1.0) -> 1
A22: =IFERROR(__xludf.DUMMYFUNCTION("""COMPUTED_VALUE"""),46303.0) -> 46303 | B22: =IFERROR(__xludf.DUMMYFUNCTION("""COMPUTED_VALUE"""),1180919.0) -> 1180919 | C22: =IFERROR(__xludf.DUMMYFUNCTION("""COMPUTED_VALUE"""),"100 $") -> 100 $ | D22: =IFERROR(__xludf.DUMMYFUNCTION("""COMPUTED_VALUE"""),"Расход га") -> Расход га | F22: =IFERROR(__xludf.DUMMYFUNCTION("""COMPUTED_VALUE"""),46320.0) -> 46320 | G22: =IFERROR(__xludf.DUMMYFUNCTION("""COMPUTED_VALUE"""),0.4173611111111111) -> 0.41736111 | H22: =IFERROR(__xludf.DUMMYFUNCTION("""COMPUTED_VALUE"""),"Rahbarga (shaxsiy)") -> Rahbarga (shaxsiy) | I22: =IFERROR(__xludf.DUMMYFUNCTION("""COMPUTED_VALUE"""),45000.0) -> 45000 | K22: =IFERROR(__xludf.DUMMYFUNCTION("""COMPUTED_VALUE"""),"Обед") -> Обед | M22: =IFERROR(__xludf.DUMMYFUNCTION("""COMPUTED_VALUE"""),"Remont avto") -> Remont avto | N22: =IFERROR(__xludf.DUMMYFUNCTION("""COMPUTED_VALUE"""),50000.0) -> 50000 | O22: =IFERROR(__xludf.DUMMYFUNCTION("""COMPUTED_VALUE"""),1.0) -> 1
A23: =IFERROR(__xludf.DUMMYFUNCTION("""COMPUTED_VALUE"""),46301.0) -> 46301 | B23: =IFERROR(__xludf.DUMMYFUNCTION("""COMPUTED_VALUE"""),1177845.0) -> 1177845 | C23: =IFERROR(__xludf.DUMMYFUNCTION("""COMPUTED_VALUE"""),"100 $") -> 100 $ | D23: =IFERROR(__xludf.DUMMYFUNCTION("""COMPUTED_VALUE"""),"Расход") -> Расход | F23: =IFERROR(__xludf.DUMMYFUNCTION("""COMPUTED_VALUE"""),46320.0) -> 46320 | G23: =IFERROR(__xludf.DUMMYFUNCTION("""COMPUTED_VALUE"""),0.4166666666666667) -> 0.41666667 | H23: =IFERROR(__xludf.DUMMYFUNCTION("""COMPUTED_VALUE"""),"Ovqat") -> Ovqat | I23: =IFERROR(__xludf.DUMMYFUNCTION("""COMPUTED_VALUE"""),35000.0) -> 35000 | K23: =IFERROR(__xludf.DUMMYFUNCTION("""COMPUTED_VALUE"""),"Обед 24.10.26") -> Обед 24.10.26
F24: =IFERROR(__xludf.DUMMYFUNCTION("""COMPUTED_VALUE"""),46319.0) -> 46319 | G24: =IFERROR(__xludf.DUMMYFUNCTION("""COMPUTED_VALUE"""),0.5951388888888889) -> 0.59513889 | H24: =IFERROR(__xludf.DUMMYFUNCTION("""COMPUTED_VALUE"""),"Zapravka") -> Zapravka | I24: =IFERROR(__xludf.DUMMYFUNCTION("""COMPUTED_VALUE"""),232000.0) -> 232000 | K24: =IFERROR(__xludf.DUMMYFUNCTION("""COMPUTED_VALUE"""),"Газ") -> Газ
F25: =IFERROR(__xludf.DUMMYFUNCTION("""COMPUTED_VALUE"""),46319.0) -> 46319 | G25: =IFERROR(__xludf.DUMMYFUNCTION("""COMPUTED_VALUE"""),0.5763888888888888) -> 0.57638889 | H25: =IFERROR(__xludf.DUMMYFUNCTION("""COMPUTED_VALUE"""),"Furnitura") -> Furnitura | I25: =IFERROR(__xludf.DUMMYFUNCTION("""COMPUTED_VALUE"""),30000.0) -> 30000 | J25: =IFERROR(__xludf.DUMMYFUNCTION("""COMPUTED_VALUE"""),397.0) -> 397 | K25: =IFERROR(__xludf.DUMMYFUNCTION("""COMPUTED_VALUE"""),"Стик") -> Стик
F26: =IFERROR(__xludf.DUMMYFUNCTION("""COMPUTED_VALUE"""),46319.0) -> 46319 | G26: =IFERROR(__xludf.DUMMYFUNCTION("""COMPUTED_VALUE"""),0.42291666666666666) -> 0.42291667 | H26: =IFERROR(__xludf.DUMMYFUNCTION("""COMPUTED_VALUE"""),"Kommunal xizmatlar") -> Kommunal xizmatlar | I26: =IFERROR(__xludf.DUMMYFUNCTION("""COMPUTED_VALUE"""),20000.0) -> 20000 | K26: =IFERROR(__xludf.DUMMYFUNCTION("""COMPUTED_VALUE"""),"Газ ишхона") -> Газ ишхона
F27: =IFERROR(__xludf.DUMMYFUNCTION("""COMPUTED_VALUE"""),46319.0) -> 46319 | G27: =IFERROR(__xludf.DUMMYFUNCTION("""COMPUTED_VALUE"""),0.4222222222222222) -> 0.42222222 | H27: =IFERROR(__xludf.DUMMYFUNCTION("""COMPUTED_VALUE"""),"Kommunal xizmatlar") -> Kommunal xizmatlar | I27: =IFERROR(__xludf.DUMMYFUNCTION("""COMPUTED_VALUE"""),50000.0) -> 50000 | K27: =IFERROR(__xludf.DUMMYFUNCTION("""COMPUTED_VALUE"""),"Свет ишхона") -> Свет ишхона
F28: =IFERROR(__xludf.DUMMYFUNCTION("""COMPUTED_VALUE"""),46318.0) -> 46318 | G28: =IFERROR(__xludf.DUMMYFUNCTION("""COMPUTED_VALUE"""),0.6534722222222222) -> 0.65347222 | H28: =IFERROR(__xludf.DUMMYFUNCTION("""COMPUTED_VALUE"""),"Заказ материал") -> Заказ материал | I28: =IFERROR(__xludf.DUMMYFUNCTION("""COMPUTED_VALUE"""),358000.0) -> 358000 | J28: =IFERROR(__xludf.DUMMYFUNCTION("""COMPUTED_VALUE"""),404.0) -> 404 | K28: =IFERROR(__xludf.DUMMYFUNCTION("""COMPUTED_VALUE"""),"Кош") -> Кош
F29: =IFERROR(__xludf.DUMMYFUNCTION("""COMPUTED_VALUE"""),46318.0) -> 46318 | G29: =IFERROR(__xludf.DUMMYFUNCTION("""COMPUTED_VALUE"""),0.6395833333333333) -> 0.63958333 | H29: =IFERROR(__xludf.DUMMYFUNCTION("""COMPUTED_VALUE"""),"Ойлик (ish haqi)") -> Ойлик (ish haqi) | I29: =IFERROR(__xludf.DUMMYFUNCTION("""COMPUTED_VALUE"""),100000.0) -> 100000 | K29: =IFERROR(__xludf.DUMMYFUNCTION("""COMPUTED_VALUE"""),"Ойлик") -> Ойлик
F30: =IFERROR(__xludf.DUMMYFUNCTION("""COMPUTED_VALUE"""),46318.0) -> 46318 | G30: =IFERROR(__xludf.DUMMYFUNCTION("""COMPUTED_VALUE"""),0.6270833333333333) -> 0.62708333 | H30: =IFERROR(__xludf.DUMMYFUNCTION("""COMPUTED_VALUE"""),"Zapravka") -> Zapravka | I30: =IFERROR(__xludf.DUMMYFUNCTION("""COMPUTED_VALUE"""),374000.0) -> 374000 | K30: =IFERROR(__xludf.DUMMYFUNCTION("""COMPUTED_VALUE"""),"Газ") -> Газ
F31: =IFERROR(__xludf.DUMMYFUNCTION("""COMPUTED_VALUE"""),46318.0) -> 46318 | G31: =IFERROR(__xludf.DUMMYFUNCTION("""COMPUTED_VALUE"""),0.5875) -> 0.5875 | H31: =IFERROR(__xludf.DUMMYFUNCTION("""COMPUTED_VALUE"""),"Ovqat") -> Ovqat | I31: =IFERROR(__xludf.DUMMYFUNCTION("""COMPUTED_VALUE"""),35000.0) -> 35000 | K31: =IFERROR(__xludf.DUMMYFUNCTION("""COMPUTED_VALUE"""),"Обед озим") -> Обед озим
F32: =IFERROR(__xludf.DUMMYFUNCTION("""COMPUTED_VALUE"""),46318.0) -> 46318 | G32: =IFERROR(__xludf.DUMMYFUNCTION("""COMPUTED_VALUE"""),0.37083333333333335) -> 0.37083333 | H32: =IFERROR(__xludf.DUMMYFUNCTION("""COMPUTED_VALUE"""),"Usluga (xizmatlar)") -> Usluga (xizmatlar) | I32: =IFERROR(__xludf.DUMMYFUNCTION("""COMPUTED_VALUE"""),81000.0) -> 81000 | K32: =IFERROR(__xludf.DUMMYFUNCTION("""COMPUTED_VALUE"""),"Арра чах") -> Арра чах
F33: =IFERROR(__xludf.DUMMYFUNCTION("""COMPUTED_VALUE"""),46317.0) -> 46317 | G33: =IFERROR(__xludf.DUMMYFUNCTION("""COMPUTED_VALUE"""),0.6652777777777777) -> 0.66527778 | H33: =IFERROR(__xludf.DUMMYFUNCTION("""COMPUTED_VALUE"""),"Zapravka") -> Zapravka | I33: =IFERROR(__xludf.DUMMYFUNCTION("""COMPUTED_VALUE"""),200000.0) -> 200000 | K33: =IFERROR(__xludf.DUMMYFUNCTION("""COMPUTED_VALUE"""),"Газ чанган") -> Газ чанган
F34: =IFERROR(__xludf.DUMMYFUNCTION("""COMPUTED_VALUE"""),46317.0) -> 46317 | G34: =IFERROR(__xludf.DUMMYFUNCTION("""COMPUTED_VALUE"""),0.6618055555555555) -> 0.66180556 | H34: =IFERROR(__xludf.DUMMYFUNCTION("""COMPUTED_VALUE"""),"Ovqat") -> Ovqat | I34: =IFERROR(__xludf.DUMMYFUNCTION("""COMPUTED_VALUE"""),35000.0) -> 35000 | K34: =IFERROR(__xludf.DUMMYFUNCTION("""COMPUTED_VALUE"""),"Обед озим") -> Обед озим
F35: =IFERROR(__xludf.DUMMYFUNCTION("""COMPUTED_VALUE"""),46316.0) -> 46316 | G35: =IFERROR(__xludf.DUMMYFUNCTION("""COMPUTED_VALUE"""),0.7597222222222222) -> 0.75972222 | H35: =IFERROR(__xludf.DUMMYFUNCTION("""COMPUTED_VALUE"""),"Rahbarga (shaxsiy)") -> Rahbarga (shaxsiy) | I35: =IFERROR(__xludf.DUMMYFUNCTION("""COMPUTED_VALUE"""),35000.0) -> 35000 | K35: =IFERROR(__xludf.DUMMYFUNCTION("""COMPUTED_VALUE"""),"Обед") -> Обед
F36: =IFERROR(__xludf.DUMMYFUNCTION("""COMPUTED_VALUE"""),46316.0) -> 46316 | G36: =IFERROR(__xludf.DUMMYFUNCTION("""COMPUTED_VALUE"""),0.7465277777777778) -> 0.74652778 | H36: =IFERROR(__xludf.DUMMYFUNCTION("""COMPUTED_VALUE"""),"Zapravka") -> Zapravka | I36: =IFERROR(__xludf.DUMMYFUNCTION("""COMPUTED_VALUE"""),100000.0) -> 100000 | K36: =IFERROR(__xludf.DUMMYFUNCTION("""COMPUTED_VALUE"""),"Бензин") -> Бензин
F37: =IFERROR(__xludf.DUMMYFUNCTION("""COMPUTED_VALUE"""),46316.0) -> 46316 | G37: =IFERROR(__xludf.DUMMYFUNCTION("""COMPUTED_VALUE"""),0.6569444444444444) -> 0.65694444 | H37: =IFERROR(__xludf.DUMMYFUNCTION("""COMPUTED_VALUE"""),"Ovqat") -> Ovqat | I37: =IFERROR(__xludf.DUMMYFUNCTION("""COMPUTED_VALUE"""),35000.0) -> 35000 | K37: =IFERROR(__xludf.DUMMYFUNCTION("""COMPUTED_VALUE"""),"Обед озим") -> Обед озим
F38: =IFERROR(__xludf.DUMMYFUNCTION("""COMPUTED_VALUE"""),46316.0) -> 46316 | G38: =IFERROR(__xludf.DUMMYFUNCTION("""COMPUTED_VALUE"""),0.4041666666666667) -> 0.40416667 | H38: =IFERROR(__xludf.DUMMYFUNCTION("""COMPUTED_VALUE"""),"Kommunal xizmatlar") -> Kommunal xizmatlar | I38: =IFERROR(__xludf.DUMMYFUNCTION("""COMPUTED_VALUE"""),50000.0) -> 50000 | K38: =IFERROR(__xludf.DUMMYFUNCTION("""COMPUTED_VALUE"""),"Свет ишхона") -> Свет ишхона
F39: =IFERROR(__xludf.DUMMYFUNCTION("""COMPUTED_VALUE"""),46315.0) -> 46315 | G39: =IFERROR(__xludf.DUMMYFUNCTION("""COMPUTED_VALUE"""),0.6993055555555555) -> 0.69930556 | H39: =IFERROR(__xludf.DUMMYFUNCTION("""COMPUTED_VALUE"""),"Usluga (xizmatlar)") -> Usluga (xizmatlar) | I39: =IFERROR(__xludf.DUMMYFUNCTION("""COMPUTED_VALUE"""),40000.0) -> 40000 | J39: =IFERROR(__xludf.DUMMYFUNCTION("""COMPUTED_VALUE"""),391.0) -> 391 | K39: =IFERROR(__xludf.DUMMYFUNCTION("""COMPUTED_VALUE"""),"Кромка") -> Кромка
F40: =IFERROR(__xludf.DUMMYFUNCTION("""COMPUTED_VALUE"""),46315.0) -> 46315 | G40: =IFERROR(__xludf.DUMMYFUNCTION("""COMPUTED_VALUE"""),0.6993055555555555) -> 0.69930556 | H40: =IFERROR(__xludf.DUMMYFUNCTION("""COMPUTED_VALUE"""),"Ovqat") -> Ovqat | I40: =IFERROR(__xludf.DUMMYFUNCTION("""COMPUTED_VALUE"""),35000.0) -> 35000 | K40: =IFERROR(__xludf.DUMMYFUNCTION("""COMPUTED_VALUE"""),"Обед озим") -> Обед озим
F41: =IFERROR(__xludf.DUMMYFUNCTION("""COMPUTED_VALUE"""),46315.0) -> 46315 | G41: =IFERROR(__xludf.DUMMYFUNCTION("""COMPUTED_VALUE"""),0.6069444444444444) -> 0.60694444 | H41: =IFERROR(__xludf.DUMMYFUNCTION("""COMPUTED_VALUE"""),"Zapravka") -> Zapravka | I41: =IFERROR(__xludf.DUMMYFUNCTION("""COMPUTED_VALUE"""),200000.0) -> 200000 | K41: =IFERROR(__xludf.DUMMYFUNCTION("""COMPUTED_VALUE"""),"Газ") -> Газ
F42: =IFERROR(__xludf.DUMMYFUNCTION("""COMPUTED_VALUE"""),46315.0) -> 46315 | G42: =IFERROR(__xludf.DUMMYFUNCTION("""COMPUTED_VALUE"""),0.5916666666666667) -> 0.59166667 | H42: =IFERROR(__xludf.DUMMYFUNCTION("""COMPUTED_VALUE"""),"Furnitura") -> Furnitura | I42: =IFERROR(__xludf.DUMMYFUNCTION("""COMPUTED_VALUE"""),30000.0) -> 30000 | J42: =IFERROR(__xludf.DUMMYFUNCTION("""COMPUTED_VALUE"""),388.0) -> 388 | K42: =IFERROR(__xludf.DUMMYFUNCTION("""COMPUTED_VALUE"""),"Паста шпаклевка") -> Паста шпаклевка
...

Sheet Ishchi kartasi
A1: 👷 Ishchi kartasi — kim qancha oylik olgan, qachon va nima uchun | Y1: =IFERROR(__xludf.DUMMYFUNCTION("ARRAYFORMULA(IFERROR(IF(COUNTIF(Ishchilar!B:B,$B$3),$B$3,INDEX(FILTER(Ishchilar!B2:B1001,Ishchilar!B2:B1001<>"""",ISNUMBER(SEARCH("" ""&Ishchilar!B2:B1001&"" "","" ""&SUBSTITUTE(SUBSTITUTE($B$3&"""",""°"","" ""),""•"","" "")&"" ""))),1)),$B$3))"),"Dilmurod") -> Dilmurod | Z1: =IFERROR(__xludf.DUMMYFUNCTION("LET(a,{Ishchilar!B2:B1001;IFERROR(FILTER(Amallar!R2:R1001,Amallar!K2:K1001=""oylik""),"""")},SORT(UNIQUE(FILTER(a,a<>""""))))"),3.0) -> 3
A2: Bu yerda faqat oylik. Umid va Islomga ish uchun bergan pullaringiz → «💸 Xarajat puli» varag'ida. | Y2: =IFERROR(__xludf.DUMMYFUNCTION("ARRAYFORMULA(IFERROR(IF(COUNTIF(Xodimlar!B:B,$B$3),$B$3,INDEX(FILTER(Xodimlar!B2:B1001,Xodimlar!B2:B1001<>"""",ISNUMBER(SEARCH("" ""&$B$3&"" "","" ""&SUBSTITUTE(SUBSTITUTE(Xodimlar!B2:B1001&"""",""°"","" ""),""•"","" "")&"" ""))),1)),$B$3))"),"Dilmurod") -> Dilmurod | Z2: =IFERROR(__xludf.DUMMYFUNCTION("""COMPUTED_VALUE"""),"Axmadilla") -> Axmadilla
A3: 👤 Ishchi: | B3: Dilmurod | E3: ← katakni bosing va ro'yxatdan ismni tanlang | Z3: =IFERROR(__xludf.DUMMYFUNCTION("""COMPUTED_VALUE"""),"Baxodir") -> Baxodir
A4: 📅 Davr: | B4: 46289 | C4: gacha: | D4: 46319 | E4: ← ikkala sanani ham ikki marta bosing — kalendar ochiladi | Z4: =IFERROR(__xludf.DUMMYFUNCTION("""COMPUTED_VALUE"""),"Dilmurod") -> Dilmurod
A5: Bo'lim / lavozim: | B5: {=IFERROR(INDEX(Ishchilar!A:A,MATCH($Y$1,Ishchilar!B:B,0))&IF(INDEX(Ishchilar!C:C,MATCH($Y$1,Ishchilar!B:B,0))="",""," · "&INDEX(Ishchilar!C:C,MATCH($Y$1,Ishchilar!B:B,0))),"—")} -> 1-komanda (sborka-ustanovka) · bosh usta | Z5: =IFERROR(__xludf.DUMMYFUNCTION("""COMPUTED_VALUE"""),"Doston") -> Doston
Z6: =IFERROR(__xludf.DUMMYFUNCTION("""COMPUTED_VALUE"""),"Elbek") -> Elbek
A7: 💵 Avans (shu davrda) | C7: 🧾 Oylik (shu davrda) | E7: 💰 Jami (shu davrda) | G7: 📝 Necha marta · oxirgi | Z7: =IFERROR(__xludf.DUMMYFUNCTION("""COMPUTED_VALUE"""),"Elyor") -> Elyor
A8: =SUMIFS(Amallar!G:G,Amallar!R:R,$Y$1,Amallar!K:K,"oylik",Amallar!F:F,"Chiqim",Amallar!S:S,"Avans",Amallar!B:B,">="&$B$4,Amallar!B:B,"<"&($D$4+1),Amallar!Q:Q,"<>Ha") -> 20991106 | C8: =SUMIFS(Amallar!G:G,Amallar!R:R,$Y$1,Amallar!K:K,"oylik",Amallar!F:F,"Chiqim",Amallar!S:S,"Oylik",Amallar!B:B,">="&$B$4,Amallar!B:B,"<"&($D$4+1),Amallar!Q:Q,"<>Ha") -> 0 | E8: =SUMIFS(Amallar!G:G,Amallar!R:R,$Y$1,Amallar!K:K,"oylik",Amallar!F:F,"Chiqim",Amallar!B:B,">="&$B$4,Amallar!B:B,"<"&($D$4+1),Amallar!Q:Q,"<>Ha") -> 20991106 | G8: =COUNTIFS(Amallar!R:R,$Y$1,Amallar!K:K,"oylik",Amallar!F:F,"Chiqim",Amallar!B:B,">="&$B$4,Amallar!B:B,"<"&($D$4+1),Amallar!Q:Q,"<>Ha")&" marta · "&IFERROR(TEXT(MAXIFS(Amallar!B:B,Amallar!R:R,$Y$1,Amallar!K:K,"oylik",Amallar!F:F,"Chiqim",Amallar!Q:Q,"<>Ha"),"dd.mm.yyyy"),"—") -> 8 marta · 20.10.2026 | Z8: =IFERROR(__xludf.DUMMYFUNCTION("""COMPUTED_VALUE"""),"Islom") -> Islom
Z9: =IFERROR(__xludf.DUMMYFUNCTION("""COMPUTED_VALUE"""),"Izzatilla") -> Izzatilla
A10: 👤 Kim bergan | E10: 📋 Har bir oylik (yangisi tepada) | Z10: =IFERROR(__xludf.DUMMYFUNCTION("""COMPUTED_VALUE"""),"Jalol") -> Jalol
A11: =IFERROR(__xludf.DUMMYFUNCTION("IFERROR(QUERY(FILTER({Amallar!E2:E1001,Amallar!G2:G1001},Amallar!R2:R1001=$Y$1,Amallar!K2:K1001=""oylik"",Amallar!F2:F1001=""Chiqim"",Amallar!Q2:Q1001<>""Ha"",Amallar!B2:B1001>=$B$4,Amallar!B2:B1001<$D$4+1),""select Col1, sum(Col2), count(Col2) group by C"&"ol1 order by sum(Col2) desc label Col1 'Kim bergan', sum(Col2) 'Summa', count(Col2) 'Soni'"",0),""— oylik yo'q"")"),"Kim bergan") -> Kim bergan | B11: =IFERROR(__xludf.DUMMYFUNCTION("""COMPUTED_VALUE"""),"Summa") -> Summa | C11: =IFERROR(__xludf.DUMMYFUNCTION("""COMPUTED_VALUE"""),"Soni") -> Soni | E11: Sana | F11: Vaqt | G11: Summa (so'm) | H11: Dollarda | I11: Kim berdi | J11: Izoh (nima uchun) | K11: Turi | Z11: =IFERROR(__xludf.DUMMYFUNCTION("""COMPUTED_VALUE"""),"Jamshid") -> Jamshid
A12: =IFERROR(__xludf.DUMMYFUNCTION("""COMPUTED_VALUE"""),"МирМуxаммад Файзуллаев") -> МирМуxаммад Файзуллаев | B12: =IFERROR(__xludf.DUMMYFUNCTION("""COMPUTED_VALUE"""),2.0751106E7) -> 20751106 | C12: =IFERROR(__xludf.DUMMYFUNCTION("""COMPUTED_VALUE"""),5.0) -> 5 | E12: =IFERROR(__xludf.DUMMYFUNCTION("IFERROR(ARRAYFORMULA(SORT(FILTER({Amallar!B2:B1001,Amallar!C2:C1001,Amallar!G2:G1001,IF(Amallar!H2:H1001=""USD"",Amallar!I2:I1001&"" $"",""""),Amallar!E2:E1001,Amallar!N2:N1001,IF(Amallar!S2:S1001=""Oylik"",""🧾 Oylik"",""💵 Avans"")},Amallar!R2:R1001=$Y$"&"1,Amallar!K2:K1001=""oylik"",Amallar!F2:F1001=""Chiqim"",Amallar!Q2:Q1001<>""Ha"",Amallar!B2:B1001>=$B$4,Amallar!B2:B1001<$D$4+1),1,FALSE,2,FALSE)),""— bu davrda oylik yo'q"")"),46315.0) -> 46315 | F12: =IFERROR(__xludf.DUMMYFUNCTION("""COMPUTED_VALUE"""),0.7770833333333333) -> 0.77708333 | G12: =IFERROR(__xludf.DUMMYFUNCTION("""COMPUTED_VALUE"""),3613416.0) -> 3613416 | H12: =IFERROR(__xludf.DUMMYFUNCTION("""COMPUTED_VALUE"""),"300 $") -> 300 $ | I12: =IFERROR(__xludf.DUMMYFUNCTION("""COMPUTED_VALUE"""),"МирМуxаммад Файзуллаев") -> МирМуxаммад Файзуллаев | J12: =IFERROR(__xludf.DUMMYFUNCTION("""COMPUTED_VALUE"""),"oylik dilmurod elbek") -> oylik dilmurod elbek | K12: =IFERROR(__xludf.DUMMYFUNCTION("""COMPUTED_VALUE"""),"💵 Avans") -> 💵 Avans | Z12: =IFERROR(__xludf.DUMMYFUNCTION("""COMPUTED_VALUE"""),"Jasur") -> Jasur
A13: =IFERROR(__xludf.DUMMYFUNCTION("""COMPUTED_VALUE"""),"°°•• Gafurov Islom ••°°") -> °°•• Gafurov Islom ••°° | B13: =IFERROR(__xludf.DUMMYFUNCTION("""COMPUTED_VALUE"""),240000.0) -> 240000 | C13: =IFERROR(__xludf.DUMMYFUNCTION("""COMPUTED_VALUE"""),3.0) -> 3 | E13: =IFERROR(__xludf.DUMMYFUNCTION("""COMPUTED_VALUE"""),46314.0) -> 46314 | F13: =IFERROR(__xludf.DUMMYFUNCTION("""COMPUTED_VALUE"""),0.7194444444444444) -> 0.71944444 | G13: =IFERROR(__xludf.DUMMYFUNCTION("""COMPUTED_VALUE"""),3000000.0) -> 3000000 | H13: =IFERROR(__xludf.DUMMYFUNCTION("""COMPUTED_VALUE"""),"") | I13: =IFERROR(__xludf.DUMMYFUNCTION("""COMPUTED_VALUE"""),"МирМуxаммад Файзуллаев") -> МирМуxаммад Файзуллаев | J13: =IFERROR(__xludf.DUMMYFUNCTION("""COMPUTED_VALUE"""),"oylik dilmurodaka shogirtga") -> oylik dilmurodaka shogirtga | K13: =IFERROR(__xludf.DUMMYFUNCTION("""COMPUTED_VALUE"""),"💵 Avans") -> 💵 Avans | Z13: =IFERROR(__xludf.DUMMYFUNCTION("""COMPUTED_VALUE"""),"Jumaka") -> Jumaka
E14: =IFERROR(__xludf.DUMMYFUNCTION("""COMPUTED_VALUE"""),46307.0) -> 46307 | F14: =IFERROR(__xludf.DUMMYFUNCTION("""COMPUTED_VALUE"""),0.7201388888888889) -> 0.72013889 | G14: =IFERROR(__xludf.DUMMYFUNCTION("""COMPUTED_VALUE"""),1.18979E7) -> 11897900 | H14: =IFERROR(__xludf.DUMMYFUNCTION("""COMPUTED_VALUE"""),"1000 $") -> 1000 $ | I14: =IFERROR(__xludf.DUMMYFUNCTION("""COMPUTED_VALUE"""),"МирМуxаммад Файзуллаев") -> МирМуxаммад Файзуллаев | J14: =IFERROR(__xludf.DUMMYFUNCTION("""COMPUTED_VALUE"""),"oylik dilmurodaka moshina arenda") -> oylik dilmurodaka moshina arenda | K14: =IFERROR(__xludf.DUMMYFUNCTION("""COMPUTED_VALUE"""),"💵 Avans") -> 💵 Avans | Z14: =IFERROR(__xludf.DUMMYFUNCTION("""COMPUTED_VALUE"""),"Maftuna") -> Maftuna
E15: =IFERROR(__xludf.DUMMYFUNCTION("""COMPUTED_VALUE"""),46307.0) -> 46307 | F15: =IFERROR(__xludf.DUMMYFUNCTION("""COMPUTED_VALUE"""),0.7152777777777778) -> 0.71527778 | G15: =IFERROR(__xludf.DUMMYFUNCTION("""COMPUTED_VALUE"""),1189790.0) -> 1189790 | H15: =IFERROR(__xludf.DUMMYFUNCTION("""COMPUTED_VALUE"""),"100 $") -> 100 $ | I15: =IFERROR(__xludf.DUMMYFUNCTION("""COMPUTED_VALUE"""),"МирМуxаммад Файзуллаев") -> МирМуxаммад Файзуллаев | J15: =IFERROR(__xludf.DUMMYFUNCTION("""COMPUTED_VALUE"""),"oylik dilmurodaka tugilgan kun") -> oylik dilmurodaka tugilgan kun | K15: =IFERROR(__xludf.DUMMYFUNCTION("""COMPUTED_VALUE"""),"💵 Avans") -> 💵 Avans | Z15: =IFERROR(__xludf.DUMMYFUNCTION("""COMPUTED_VALUE"""),"Mexriniso") -> Mexriniso
E16: =IFERROR(__xludf.DUMMYFUNCTION("""COMPUTED_VALUE"""),46307.0) -> 46307 | F16: =IFERROR(__xludf.DUMMYFUNCTION("""COMPUTED_VALUE"""),0.6694444444444444) -> 0.66944444 | G16: =IFERROR(__xludf.DUMMYFUNCTION("""COMPUTED_VALUE"""),1050000.0) -> 1050000 | H16: =IFERROR(__xludf.DUMMYFUNCTION("""COMPUTED_VALUE"""),"") | I16: =IFERROR(__xludf.DUMMYFUNCTION("""COMPUTED_VALUE"""),"МирМуxаммад Файзуллаев") -> МирМуxаммад Файзуллаев | J16: =IFERROR(__xludf.DUMMYFUNCTION("""COMPUTED_VALUE"""),"oylik dilmurodaka shogirtga berganla") -> oylik dilmurodaka shogirtga berganla | K16: =IFERROR(__xludf.DUMMYFUNCTION("""COMPUTED_VALUE"""),"💵 Avans") -> 💵 Avans | Z16: =IFERROR(__xludf.DUMMYFUNCTION("""COMPUTED_VALUE"""),"Mirjamol") -> Mirjamol
E17: =IFERROR(__xludf.DUMMYFUNCTION("""COMPUTED_VALUE"""),46305.0) -> 46305 | F17: =IFERROR(__xludf.DUMMYFUNCTION("""COMPUTED_VALUE"""),0.8243055555555555) -> 0.82430556 | G17: =IFERROR(__xludf.DUMMYFUNCTION("""COMPUTED_VALUE"""),20000.0) -> 20000 | H17: =IFERROR(__xludf.DUMMYFUNCTION("""COMPUTED_VALUE"""),"") | I17: =IFERROR(__xludf.DUMMYFUNCTION("""COMPUTED_VALUE"""),"°°•• Gafurov Islom ••°°") -> °°•• Gafurov Islom ••°° | J17: =IFERROR(__xludf.DUMMYFUNCTION("""COMPUTED_VALUE"""),"Стадион Элбек ойлик") -> Стадион Элбек ойлик | K17: =IFERROR(__xludf.DUMMYFUNCTION("""COMPUTED_VALUE"""),"💵 Avans") -> 💵 Avans | Z17: =IFERROR(__xludf.DUMMYFUNCTION("""COMPUTED_VALUE"""),"Mumina") -> Mumina
E18: =IFERROR(__xludf.DUMMYFUNCTION("""COMPUTED_VALUE"""),46305.0) -> 46305 | F18: =IFERROR(__xludf.DUMMYFUNCTION("""COMPUTED_VALUE"""),0.8090277777777778) -> 0.80902778 | G18: =IFERROR(__xludf.DUMMYFUNCTION("""COMPUTED_VALUE"""),20000.0) -> 20000 | H18: =IFERROR(__xludf.DUMMYFUNCTION("""COMPUTED_VALUE"""),"") | I18: =IFERROR(__xludf.DUMMYFUNCTION("""COMPUTED_VALUE"""),"°°•• Gafurov Islom ••°°") -> °°•• Gafurov Islom ••°° | J18: =IFERROR(__xludf.DUMMYFUNCTION("""COMPUTED_VALUE"""),"Стадион") -> Стадион | K18: =IFERROR(__xludf.DUMMYFUNCTION("""COMPUTED_VALUE"""),"💵 Avans") -> 💵 Avans | Z18: =IFERROR(__xludf.DUMMYFUNCTION("""COMPUTED_VALUE"""),"Muxabbat opa") -> Muxabbat opa
E19: =IFERROR(__xludf.DUMMYFUNCTION("""COMPUTED_VALUE"""),46305.0) -> 46305 | F19: =IFERROR(__xludf.DUMMYFUNCTION("""COMPUTED_VALUE"""),0.0625) -> 0.0625 | G19: =IFERROR(__xludf.DUMMYFUNCTION("""COMPUTED_VALUE"""),200000.0) -> 200000 | H19: =IFERROR(__xludf.DUMMYFUNCTION("""COMPUTED_VALUE"""),"") | I19: =IFERROR(__xludf.DUMMYFUNCTION("""COMPUTED_VALUE"""),"°°•• Gafurov Islom ••°°") -> °°•• Gafurov Islom ••°° | J19: =IFERROR(__xludf.DUMMYFUNCTION("""COMPUTED_VALUE"""),"Элбек аванс") -> Элбек аванс | K19: =IFERROR(__xludf.DUMMYFUNCTION("""COMPUTED_VALUE"""),"💵 Avans") -> 💵 Avans | Z19: =IFERROR(__xludf.DUMMYFUNCTION("""COMPUTED_VALUE"""),"Nafisa") -> Nafisa
Z20: =IFERROR(__xludf.DUMMYFUNCTION("""COMPUTED_VALUE"""),"Nurilla") -> Nurilla
Z21: =IFERROR(__xludf.DUMMYFUNCTION("""COMPUTED_VALUE"""),"Rovshan") -> Rovshan
Z22: =IFERROR(__xludf.DUMMYFUNCTION("""COMPUTED_VALUE"""),"Shavkataka") -> Shavkataka
Z23: =IFERROR(__xludf.DUMMYFUNCTION("""COMPUTED_VALUE"""),"Ulug'bek aka") -> Ulug'bek aka
Z24: =IFERROR(__xludf.DUMMYFUNCTION("""COMPUTED_VALUE"""),"Umid") -> Umid
Z25: =IFERROR(__xludf.DUMMYFUNCTION("""COMPUTED_VALUE"""),"Yulduz") -> Yulduz

Sheet Mijoz kartasi
A1: 🧾 Mijoz kartasi — mijoz ID bo'yicha hamma ma'lumot | Y1: =IFERROR(__xludf.DUMMYFUNCTION("IFERROR(REGEXEXTRACT($B$3&"""",""^\d+""),TRIM($B$3&""""))"),"395") -> 395 | Z1: =IFERROR(__xludf.DUMMYFUNCTION("ARRAYFORMULA(LET(ids,UNIQUE(FILTER({Amallar!M2:M1000&"""";Buyurtmalar!A2:A1000&""""},{Amallar!M2:M1000&"""";Buyurtmalar!A2:A1000&""""}<>"""")),nm,MAP(ids,LAMBDA(i,IFERROR(INDEX(FILTER(Buyurtmalar!B2:B1000,Buyurtmalar!A2:A1000&""""=i),1),""""))),SORT(ids&I"&"F(nm="""","""","" · ""&nm),IFERROR(VALUE(ids),0),FALSE)))"),"410 · Murod aka") -> 410 · Murod aka
Y2: =IFERROR(__xludf.DUMMYFUNCTION("IFERROR(VALUE(INDEX(FILTER(Buyurtmalar!Q2:Q1000,Buyurtmalar!A2:A1000&""""=$Y$1),1)&""""),0)"),12103.0) -> 12103 | Z2: =IFERROR(__xludf.DUMMYFUNCTION("""COMPUTED_VALUE"""),"409 · НИЛУФАР ОПА") -> 409 · НИЛУФАР ОПА
A3: 🧾 Mijoz: | B3: 395 · БЕКЗОД | E3: ← katakni bosing va ro'yxatdan mijozni tanlang (yoki ID yozing) | Y3: =IFERROR(__xludf.DUMMYFUNCTION("IFERROR(INDEX(FILTER(Buyurtmalar!R2:R1000,Buyurtmalar!A2:A1000&""""=$Y$1),1)&"""","""")"),"USD") -> USD | Z3: =IFERROR(__xludf.DUMMYFUNCTION("""COMPUTED_VALUE"""),"408 · BUNYOD") -> 408 · BUNYOD
A4: Mijoz ismi: | B4: =IFERROR(__xludf.DUMMYFUNCTION("IFERROR(INDEX(FILTER(Buyurtmalar!B2:B1000,Buyurtmalar!A2:A1000&""""=$Y$1),1),""— jadvalda yo'q"")"),"БЕКЗОД") -> БЕКЗОД | D4: Holat: | E4: =IFERROR(__xludf.DUMMYFUNCTION("IFERROR(LET(s,INDEX(FILTER(Buyurtmalar!N2:N1000,Buyurtmalar!A2:A1000&""""=$Y$1),1),h,INDEX(FILTER(Buyurtmalar!F2:F1000,Buyurtmalar!A2:A1000&""""=$Y$1),1),IF(s="""",h,s)),""—"")"),"Готов") -> Готов | G4: Mijozdan olindi: | H4: =SUMPRODUCT((Amallar!M2:M1000&""=$Y$1)*(Amallar!F2:F1000="Kirim")*(Amallar!Q2:Q1000<>"Ha")*((Amallar!K2:K1000="avans")+(Amallar!K2:K1000="qoldiq"))*Amallar!G2:G1000) -> 30975700 | Y4: =IFERROR(__xludf.DUMMYFUNCTION("IFERROR(INDEX(SORT(FILTER({Amallar!B2:B1000,Amallar!J2:J1000},Amallar!H2:H1000=""USD"",Amallar!J2:J1000<>""""),1,FALSE),1,2),IFERROR(GOOGLEFINANCE(""CURRENCY:USDUZS""),12000))"),11900.0) -> 11900 | Z4: =IFERROR(__xludf.DUMMYFUNCTION("""COMPUTED_VALUE"""),"407 · Mohir aka") -> 407 · Mohir aka
A5: Итого (sayt): | B5: =IFERROR(__xludf.DUMMYFUNCTION("IFERROR(LET(v,INDEX(FILTER(Buyurtmalar!Q2:Q1000,Buyurtmalar!A2:A1000&""""=$Y$1),1),c,INDEX(FILTER(Buyurtmalar!R2:R1000,Buyurtmalar!A2:A1000&""""=$Y$1),1),IF(v="""",""—"",IF(c=""USD"",TEXT(v,""#,##0"")&"" $"",TEXT(v,""#,##0"")&"" so'm""))),""—"")"),"12,103 $") -> 12,103 $ | D5: Topshirish sanasi: | E5: =IFERROR(__xludf.DUMMYFUNCTION("IFERROR(TEXT(INDEX(FILTER(Buyurtmalar!O2:O1000,Buyurtmalar!A2:A1000&""""=$Y$1),1),""dd.mm.yyyy""),""—"")"),"12.10.2026") -> 12.10.2026 | G5: Dollar kursi: | H5: =$Y$4 -> 11900 | Y5: =IF($Y$3="USD",$Y$2*$Y$4,$Y$2) -> 144025700 | Z5: =IFERROR(__xludf.DUMMYFUNCTION("""COMPUTED_VALUE"""),"406 · НАЗИРА") -> 406 · НАЗИРА
A6: Mebel turi: | B6: =IFERROR(__xludf.DUMMYFUNCTION("IFERROR(INDEX(FILTER(Buyurtmalar!S2:S1000,Buyurtmalar!A2:A1000&""""=$Y$1),1),""—"")"),"ПОЛНЫЙ ДОМ (АКРИЛ)") -> ПОЛНЫЙ ДОМ (АКРИЛ) | D6: Manzil: | E6: =IFERROR(__xludf.DUMMYFUNCTION("IFERROR(INDEX(FILTER(Buyurtmalar!P2:P1000,Buyurtmalar!A2:A1000&""""=$Y$1),1),""—"")"),"Самарканд дарвоза") -> Самарканд дарвоза | Y6: =SUMPRODUCT((Amallar!M2:M1000&""=$Y$1)*(Amallar!F2:F1000="Chiqim")*(Amallar!Q2:Q1000<>"Ha")*(Amallar!K2:K1000<>"otkazma")*(Amallar!K2:K1000<>"rahbarga")*(Amallar!K2:K1000<>"uy")*Amallar!G2:G1000) -> 5584000 | Z6: =IFERROR(__xludf.DUMMYFUNCTION("""COMPUTED_VALUE"""),"405 · НАИМА ОПА") -> 405 · НАИМА ОПА
A7: 💼 Итого (so'm va $) | C7: 🔴 Jami xarajat | E7: 💰 FOYDA (Итого − xarajat) | G7: 📊 Foyda foizi | Y7: =$Y$5-$Y$6 -> 138441700 | Z7: =IFERROR(__xludf.DUMMYFUNCTION("""COMPUTED_VALUE"""),"404 · ФЕРУЗА ОПА") -> 404 · ФЕРУЗА ОПА
A8: =TEXT($Y$5,"#,##0")&" so'm"&CHAR(10)&TEXT(IF($Y$3="USD",$Y$2,IFERROR($Y$2/$Y$4,0)),"#,##0")&" $" -> 144,025,700 so'm 12,103 $ | C8: =TEXT($Y$6,"#,##0")&" so'm"&CHAR(10)&TEXT(IFERROR($Y$6/$Y$4,0),"#,##0")&" $" -> 5,584,000 so'm 469 $ | E8: =IF($Y$7<0,"−","")&TEXT(ABS($Y$7),"#,##0")&" so'm"&CHAR(10)&IF($Y$7<0,"−","")&TEXT(IFERROR(ABS($Y$7)/$Y$4,0),"#,##0")&" $" -> 138,441,700 so'm 11,634 $ | G8: =IFERROR($Y$7/$Y$5,0) -> 0.96122914 | Z8: =IFERROR(__xludf.DUMMYFUNCTION("""COMPUTED_VALUE"""),"403 · Ezoza opa") -> 403 · Ezoza opa
Z9: =IFERROR(__xludf.DUMMYFUNCTION("""COMPUTED_VALUE"""),"402 · GABIDEN AKA") -> 402 · GABIDEN AKA
A10: 📊 Xarajat turlari | E10: 📋 Barcha amallar — kirim va chiqim (yangisi tepada) | Z10: =IFERROR(__xludf.DUMMYFUNCTION("""COMPUTED_VALUE"""),"401 · Aziza opa") -> 401 · Aziza opa
A11: =IFERROR(__xludf.DUMMYFUNCTION("IFERROR(QUERY(FILTER({Amallar!L2:L1000,Amallar!G2:G1000},(Amallar!M2:M1000&""""=$Y$1),Amallar!F2:F1000=""Chiqim"",Amallar!Q2:Q1000<>""Ha""),""select Col1, sum(Col2), count(Col2) group by Col1 order by sum(Col2) desc label Col1 'Turi', sum(Col2) 'Summa', c"&"ount(Col2) 'Soni'"",0),""— xarajat yo'q"")"),"Turi") -> Turi | B11: =IFERROR(__xludf.DUMMYFUNCTION("""COMPUTED_VALUE"""),"Summa") -> Summa | C11: =IFERROR(__xludf.DUMMYFUNCTION("""COMPUTED_VALUE"""),"Soni") -> Soni | E11: Sana | F11: Vaqt | G11: Xodim | H11: Turi | I11: Kategoriya | J11: Summa (so'm) | K11: Izoh | Z11: =IFERROR(__xludf.DUMMYFUNCTION("""COMPUTED_VALUE"""),"400 · Гулмирапа") -> 400 · Гулмирапа
A12: =IFERROR(__xludf.DUMMYFUNCTION("""COMPUTED_VALUE"""),"Xodimlar o'rtasida o'tkazma") -> Xodimlar o'rtasida o'tkazma | B12: =IFERROR(__xludf.DUMMYFUNCTION("""COMPUTED_VALUE"""),3.09757E7) -> 30975700 | C12: =IFERROR(__xludf.DUMMYFUNCTION("""COMPUTED_VALUE"""),1.0) -> 1 | E12: =IFERROR(__xludf.DUMMYFUNCTION("IFERROR(SORT(FILTER({Amallar!B2:B1000,Amallar!C2:C1000,Amallar!E2:E1000,Amallar!F2:F1000,Amallar!L2:L1000,Amallar!G2:G1000,Amallar!N2:N1000},(Amallar!M2:M1000&""""=$Y$1),Amallar!Q2:Q1000<>""Ha""),1,FALSE,2,FALSE),""— bu ID bo'yicha yozuv yo'q"")"),46319.0) -> 46319 | F12: =IFERROR(__xludf.DUMMYFUNCTION("""COMPUTED_VALUE"""),0.6444444444444445) -> 0.64444444 | G12: =IFERROR(__xludf.DUMMYFUNCTION("""COMPUTED_VALUE"""),"Umid Yusupov") -> Umid Yusupov | H12: =IFERROR(__xludf.DUMMYFUNCTION("""COMPUTED_VALUE"""),"Chiqim") -> Chiqim | I12: =IFERROR(__xludf.DUMMYFUNCTION("""COMPUTED_VALUE"""),"Xodimlar o'rtasida o'tkazma") -> Xodimlar o'rtasida o'tkazma | J12: =IFERROR(__xludf.DUMMYFUNCTION("""COMPUTED_VALUE"""),3.09757E7) -> 30975700 | K12: =IFERROR(__xludf.DUMMYFUNCTION("""COMPUTED_VALUE"""),"Rahbarga topshirdi: 395 · БЕКЗОД (#408)") -> Rahbarga topshirdi: 395 · БЕКЗОД (#408) | Z12: =IFERROR(__xludf.DUMMYFUNCTION("""COMPUTED_VALUE"""),"399 · АЛИЖОН АКА") -> 399 · АЛИЖОН АКА
A13: =IFERROR(__xludf.DUMMYFUNCTION("""COMPUTED_VALUE"""),"Заказ материал") -> Заказ материал | B13: =IFERROR(__xludf.DUMMYFUNCTION("""COMPUTED_VALUE"""),2250000.0) -> 2250000 | C13: =IFERROR(__xludf.DUMMYFUNCTION("""COMPUTED_VALUE"""),1.0) -> 1 | E13: =IFERROR(__xludf.DUMMYFUNCTION("""COMPUTED_VALUE"""),46319.0) -> 46319 | F13: =IFERROR(__xludf.DUMMYFUNCTION("""COMPUTED_VALUE"""),0.6444444444444445) -> 0.64444444 | G13: =IFERROR(__xludf.DUMMYFUNCTION("""COMPUTED_VALUE"""),"МирМуxаммад Файзуллаев") -> МирМуxаммад Файзуллаев | H13: =IFERROR(__xludf.DUMMYFUNCTION("""COMPUTED_VALUE"""),"Kirim") -> Kirim | I13: =IFERROR(__xludf.DUMMYFUNCTION("""COMPUTED_VALUE"""),"Xodimlar o'rtasida o'tkazma") -> Xodimlar o'rtasida o'tkazma | J13: =IFERROR(__xludf.DUMMYFUNCTION("""COMPUTED_VALUE"""),3.09757E7) -> 30975700 | K13: =IFERROR(__xludf.DUMMYFUNCTION("""COMPUTED_VALUE"""),"#418: Rahbarga topshirdi: 395 · БЕКЗОД (#408)") -> #418: Rahbarga topshirdi: 395 · БЕКЗОД (#408) | Z13: =IFERROR(__xludf.DUMMYFUNCTION("""COMPUTED_VALUE"""),"398 · СОХИБА") -> 398 · СОХИБА
A14: =IFERROR(__xludf.DUMMYFUNCTION("""COMPUTED_VALUE"""),"Furnitura") -> Furnitura | B14: =IFERROR(__xludf.DUMMYFUNCTION("""COMPUTED_VALUE"""),1630000.0) -> 1630000 | C14: =IFERROR(__xludf.DUMMYFUNCTION("""COMPUTED_VALUE"""),2.0) -> 2 | E14: =IFERROR(__xludf.DUMMYFUNCTION("""COMPUTED_VALUE"""),46318.0) -> 46318 | F14: =IFERROR(__xludf.DUMMYFUNCTION("""COMPUTED_VALUE"""),0.7430555555555556) -> 0.74305556 | G14: =IFERROR(__xludf.DUMMYFUNCTION("""COMPUTED_VALUE"""),"Umid Yusupov") -> Umid Yusupov | H14: =IFERROR(__xludf.DUMMYFUNCTION("""COMPUTED_VALUE"""),"Kirim") -> Kirim | I14: =IFERROR(__xludf.DUMMYFUNCTION("""COMPUTED_VALUE"""),"Qoldiq to'lov (bitgan zakaz)") -> Qoldiq to'lov (bitgan zakaz) | J14: =IFERROR(__xludf.DUMMYFUNCTION("""COMPUTED_VALUE"""),3.09757E7) -> 30975700 | K14: =IFERROR(__xludf.DUMMYFUNCTION("""COMPUTED_VALUE"""),"Pul oldim (mijozdan qoldiq)") -> Pul oldim (mijozdan qoldiq) | Z14: =IFERROR(__xludf.DUMMYFUNCTION("""COMPUTED_VALUE"""),"397 · XAMID AKA") -> 397 · XAMID AKA
A15: =IFERROR(__xludf.DUMMYFUNCTION("""COMPUTED_VALUE"""),"Ovqat") -> Ovqat | B15: =IFERROR(__xludf.DUMMYFUNCTION("""COMPUTED_VALUE"""),1140000.0) -> 1140000 | C15: =IFERROR(__xludf.DUMMYFUNCTION("""COMPUTED_VALUE"""),7.0) -> 7 | E15: =IFERROR(__xludf.DUMMYFUNCTION("""COMPUTED_VALUE"""),46314.0) -> 46314 | F15: =IFERROR(__xludf.DUMMYFUNCTION("""COMPUTED_VALUE"""),0.9076388888888889) -> 0.90763889 | G15: =IFERROR(__xludf.DUMMYFUNCTION("""COMPUTED_VALUE"""),"°°•• Gafurov Islom ••°°") -> °°•• Gafurov Islom ••°° | H15: =IFERROR(__xludf.DUMMYFUNCTION("""COMPUTED_VALUE"""),"Chiqim") -> Chiqim | I15: =IFERROR(__xludf.DUMMYFUNCTION("""COMPUTED_VALUE"""),"Usluga (xizmatlar)") -> Usluga (xizmatlar) | J15: =IFERROR(__xludf.DUMMYFUNCTION("""COMPUTED_VALUE"""),212000.0) -> 212000 | K15: =IFERROR(__xludf.DUMMYFUNCTION("""COMPUTED_VALUE"""),"Кромка ровер") -> Кромка ровер | Z15: =IFERROR(__xludf.DUMMYFUNCTION("""COMPUTED_VALUE"""),"396 · Mohir aka") -> 396 · Mohir aka
A16: =IFERROR(__xludf.DUMMYFUNCTION("""COMPUTED_VALUE"""),"Usluga (xizmatlar)") -> Usluga (xizmatlar) | B16: =IFERROR(__xludf.DUMMYFUNCTION("""COMPUTED_VALUE"""),504000.0) -> 504000 | C16: =IFERROR(__xludf.DUMMYFUNCTION("""COMPUTED_VALUE"""),3.0) -> 3 | E16: =IFERROR(__xludf.DUMMYFUNCTION("""COMPUTED_VALUE"""),46314.0) -> 46314 | F16: =IFERROR(__xludf.DUMMYFUNCTION("""COMPUTED_VALUE"""),0.7847222222222222) -> 0.78472222 | G16: =IFERROR(__xludf.DUMMYFUNCTION("""COMPUTED_VALUE"""),"°°•• Gafurov Islom ••°°") -> °°•• Gafurov Islom ••°° | H16: =IFERROR(__xludf.DUMMYFUNCTION("""COMPUTED_VALUE"""),"Chiqim") -> Chiqim | I16: =IFERROR(__xludf.DUMMYFUNCTION("""COMPUTED_VALUE"""),"Furnitura") -> Furnitura | J16: =IFERROR(__xludf.DUMMYFUNCTION("""COMPUTED_VALUE"""),886000.0) -> 886000 | K16: =IFERROR(__xludf.DUMMYFUNCTION("""COMPUTED_VALUE"""),"Ойна подсветка") -> Ойна подсветка | Z16: =IFERROR(__xludf.DUMMYFUNCTION("""COMPUTED_VALUE"""),"395 · БЕКЗОД") -> 395 · БЕКЗОД
A17: =IFERROR(__xludf.DUMMYFUNCTION("""COMPUTED_VALUE"""),"Mashina / dostavka") -> Mashina / dostavka | B17: =IFERROR(__xludf.DUMMYFUNCTION("""COMPUTED_VALUE"""),60000.0) -> 60000 | C17: =IFERROR(__xludf.DUMMYFUNCTION("""COMPUTED_VALUE"""),2.0) -> 2 | E17: =IFERROR(__xludf.DUMMYFUNCTION("""COMPUTED_VALUE"""),46312.0) -> 46312 | F17: =IFERROR(__xludf.DUMMYFUNCTION("""COMPUTED_VALUE"""),0.8909722222222223) -> 0.89097222 | G17: =IFERROR(__xludf.DUMMYFUNCTION("""COMPUTED_VALUE"""),"Umid Yusupov") -> Umid Yusupov | H17: =IFERROR(__xludf.DUMMYFUNCTION("""COMPUTED_VALUE"""),"Chiqim") -> Chiqim | I17: =IFERROR(__xludf.DUMMYFUNCTION("""COMPUTED_VALUE"""),"Ovqat") -> Ovqat | J17: =IFERROR(__xludf.DUMMYFUNCTION("""COMPUTED_VALUE"""),100000.0) -> 100000 | K17: =IFERROR(__xludf.DUMMYFUNCTION("""COMPUTED_VALUE"""),"Ужин сув 2 киши") -> Ужин сув 2 киши | Z17: =IFERROR(__xludf.DUMMYFUNCTION("""COMPUTED_VALUE"""),"394 · Alisher aka") -> 394 · Alisher aka
E18: =IFERROR(__xludf.DUMMYFUNCTION("""COMPUTED_VALUE"""),46312.0) -> 46312 | F18: =IFERROR(__xludf.DUMMYFUNCTION("""COMPUTED_VALUE"""),0.6958333333333333) -> 0.69583333 | G18: =IFERROR(__xludf.DUMMYFUNCTION("""COMPUTED_VALUE"""),"МирМуxаммад Файзуллаев") -> МирМуxаммад Файзуллаев | H18: =IFERROR(__xludf.DUMMYFUNCTION("""COMPUTED_VALUE"""),"Chiqim") -> Chiqim | I18: =IFERROR(__xludf.DUMMYFUNCTION("""COMPUTED_VALUE"""),"Furnitura") -> Furnitura | J18: =IFERROR(__xludf.DUMMYFUNCTION("""COMPUTED_VALUE"""),744000.0) -> 744000 | K18: =IFERROR(__xludf.DUMMYFUNCTION("""COMPUTED_VALUE"""),"begzod 395 karkaz krovat") -> begzod 395 karkaz krovat | Z18: =IFERROR(__xludf.DUMMYFUNCTION("""COMPUTED_VALUE"""),"393 · ХУСНИДДИН") -> 393 · ХУСНИДДИН
E19: =IFERROR(__xludf.DUMMYFUNCTION("""COMPUTED_VALUE"""),46311.0) -> 46311 | F19: =IFERROR(__xludf.DUMMYFUNCTION("""COMPUTED_VALUE"""),0.6138888888888889) -> 0.61388889 | G19: =IFERROR(__xludf.DUMMYFUNCTION("""COMPUTED_VALUE"""),"Umid Yusupov") -> Umid Yusupov | H19: =IFERROR(__xludf.DUMMYFUNCTION("""COMPUTED_VALUE"""),"Chiqim") -> Chiqim | I19: =IFERROR(__xludf.DUMMYFUNCTION("""COMPUTED_VALUE"""),"Mashina / dostavka") -> Mashina / dostavka | J19: =IFERROR(__xludf.DUMMYFUNCTION("""COMPUTED_VALUE"""),40000.0) -> 40000 | K19: =IFERROR(__xludf.DUMMYFUNCTION("""COMPUTED_VALUE"""),"Элбек ака уйга бориш") -> Элбек ака уйга бориш | Z19: =IFERROR(__xludf.DUMMYFUNCTION("""COMPUTED_VALUE"""),"392 · МАРХАБО") -> 392 · МАРХАБО
E20: =IFERROR(__xludf.DUMMYFUNCTION("""COMPUTED_VALUE"""),46310.0) -> 46310 | F20: =IFERROR(__xludf.DUMMYFUNCTION("""COMPUTED_VALUE"""),0.8819444444444444) -> 0.88194444 | G20: =IFERROR(__xludf.DUMMYFUNCTION("""COMPUTED_VALUE"""),"Umid Yusupov") -> Umid Yusupov | H20: =IFERROR(__xludf.DUMMYFUNCTION("""COMPUTED_VALUE"""),"Chiqim") -> Chiqim | I20: =IFERROR(__xludf.DUMMYFUNCTION("""COMPUTED_VALUE"""),"Ovqat") -> Ovqat | J20: =IFERROR(__xludf.DUMMYFUNCTION("""COMPUTED_VALUE"""),240000.0) -> 240000 | K20: =IFERROR(__xludf.DUMMYFUNCTION("""COMPUTED_VALUE"""),"Ужин 6 киши") -> Ужин 6 киши | Z20: =IFERROR(__xludf.DUMMYFUNCTION("""COMPUTED_VALUE"""),"391 · АКБАР АКА") -> 391 · АКБАР АКА
